<?xml version="1.0" ?>
<!-- =================================================================================== -->
<!-- |    This document was autogenerated by xacro from /home/mouri/workspace/install/ign_ros2_robot2world_sample/share/ign_ros2_robot2world_sample/urdf/robot.urdf.xacro | -->
<!-- |    EDITING THIS FILE BY HAND IS NOT RECOMMENDED                                 | -->
<!-- =================================================================================== -->
<robot name="model">
  <ros2_control name="arm1_GazeboSystem" type="system">
    <hardware>
      <plugin>ign_ros2_control/IgnitionSystem</plugin>
    </hardware>
    <joint name="arm1_joint_1">
      <command_interface name="position">
        <param name="min">-4.712389</param>
        <param name="max">4.712389</param>
      </command_interface>
      <command_interface name="velocity">
        <param name="min">0</param>
        <param name="max">1</param>
      </command_interface>
      <state_interface name="position"/>
      <state_interface name="velocity"/>
      <state_interface name="effort"/>
    </joint>
    <joint name="arm1_joint_2">
      <command_interface name="position">
        <param name="min">-2.617994</param>
        <param name="max">2.617994</param>
      </command_interface>
      <command_interface name="velocity">
        <param name="min">0</param>
        <param name="max">1</param>
      </command_interface>
      <state_interface name="position"/>
      <state_interface name="velocity"/>
      <state_interface name="effort"/>
    </joint>
    <joint name="arm1_joint_3">
      <command_interface name="position">
        <param name="min">-2.617994</param>
        <param name="max">2.617994</param>
      </command_interface>
      <command_interface name="velocity">
        <param name="min">0</param>
        <param name="max">1</param>
      </command_interface>
      <state_interface name="position"/>
      <state_interface name="velocity"/>
      <state_interface name="effort"/>
    </joint>
    <joint name="arm1_joint_4">
      <command_interface name="position">
        <param name="min">-4.712389</param>
        <param name="max">4.712389</param>
      </command_interface>
      <command_interface name="velocity">
        <param name="min">0</param>
        <param name="max">1</param>
      </command_interface>
      <state_interface name="position"/>
      <state_interface name="velocity"/>
      <state_interface name="effort"/>
    </joint>
    <joint name="arm1_joint_5">
      <command_interface name="position">
        <param name="min">-2.617994</param>
        <param name="max">2.617994</param>
      </command_interface>
      <command_interface name="velocity">
        <param name="min">0</param>
        <param name="max">1</param>
      </command_interface>
      <state_interface name="position"/>
      <state_interface name="velocity"/>
      <state_interface name="effort"/>
    </joint>
    <joint name="arm1_joint_6">
      <command_interface name="position">
        <param name="min">-6.283185</param>
        <param name="max">6.283185</param>
      </command_interface>
      <command_interface name="velocity">
        <param name="min">0</param>
        <param name="max">1</param>
      </command_interface>
      <state_interface name="position"/>
      <state_interface name="velocity"/>
      <state_interface name="effort"/>
    </joint>
  </ros2_control>
  <transmission name="arm1_trans_1">
    <type>transmission_interface/SimpleTransmission</type>
    <joint name="arm1_joint_1">
      <hardwareInterface></hardwareInterface>
    </joint>
    <actuator name="arm1_motor_1">
      <mechanicalReduction>1</mechanicalReduction>
    </actuator>
  </transmission>
  <transmission name="arm1_trans_2">
    <type>transmission_interface/SimpleTransmission</type>
    <joint name="arm1_joint_2">
      <hardwareInterface></hardwareInterface>
    </joint>
    <actuator name="arm1_motor_2">
      <mechanicalReduction>1</mechanicalReduction>
    </actuator>
  </transmission>
  <transmission name="arm1_trans_3">
    <type>transmission_interface/SimpleTransmission</type>
    <joint name="arm1_joint_3">
      <hardwareInterface></hardwareInterface>
    </joint>
    <actuator name="arm1_motor_3">
      <mechanicalReduction>1</mechanicalReduction>
    </actuator>
  </transmission>
  <transmission name="arm1_trans_4">
    <type>transmission_interface/SimpleTransmission</type>
    <joint name="arm1_joint_4">
      <hardwareInterface></hardwareInterface>
    </joint>
    <actuator name="arm1_motor_4">
      <mechanicalReduction>1</mechanicalReduction>
    </actuator>
  </transmission>
  <transmission name="arm1_trans_5">
    <type>transmission_interface/SimpleTransmission</type>
    <joint name="arm1_joint_5">
      <hardwareInterface></hardwareInterface>
    </joint>
    <actuator name="arm1_motor_5">
      <mechanicalReduction>1</mechanicalReduction>
    </actuator>
  </transmission>
  <transmission name="arm1_trans_6">
    <type>transmission_interface/SimpleTransmission</type>
    <joint name="arm1_joint_6">
      <hardwareInterface></hardwareInterface>
    </joint>
    <actuator name="arm1_motor_6">
      <mechanicalReduction>1</mechanicalReduction>
    </actuator>
  </transmission>
  <!-- Placeholder for ros2_control transmission which don't yet exist -->
  <link name="arm1_base_link"/>
  <joint name="arm1_base_joint" type="fixed">
    <parent link="arm1_base_link"/>
    <child link="arm1_bottom_link"/>
  </joint>
  <link name="arm1_bottom_link">
    <visual>
      <origin rpy="0 0 0" xyz="0 0 0"/>
      <geometry>
        <mesh filename="base_link.stl" scale="1 1 1"/>
      </geometry>
    </visual>
    <collision>
      <origin rpy="0 0 0" xyz="0 0 0"/>
      <geometry>
        <mesh filename="base_link.stl" scale="1 1 1"/>
      </geometry>
    </collision>
    <inertial>
      <mass value="4.0"/>
      <origin rpy="0.000000 0.000000 0.000000" xyz="0.000000 0.000000 0.000000"/>
      <inertia ixx="0.0061" ixy="0" ixz="0" iyy="0.0061" iyz="0" izz="0.01125"/>
    </inertial>
  </link>
  <link name="arm1_J1">
    <visual>
      <origin rpy="0 0 0" xyz="0 0 0"/>
      <geometry>
        <mesh filename="J1.stl" scale="1 1 1"/>
      </geometry>
    </visual>
    <collision>
      <origin rpy="0 0 0" xyz="0 0 0"/>
      <geometry>
        <mesh filename="J1.stl" scale="1 1 1"/>
      </geometry>
    </collision>
    <inertial>
      <mass value="7.778"/>
      <origin rpy="0.000000 0.000000 0.000000" xyz="0.000000 0.000000 0.000000"/>
      <inertia ixx="0.0314" ixy="0" ixz="0" iyy="0.0314" iyz="0" izz="0.0218"/>
    </inertial>
  </link>
  <joint name="arm1_joint_1" type="revolute">
    <parent link="arm1_bottom_link"/>
    <child link="arm1_J1"/>
    <origin rpy="0.000000 0.000000 0.000000" xyz="0.000000 0.000000 0.101000"/>
    <axis xyz="-0.000000 -0.000000 1.000000"/>
    <limit effort="175" lower="-4.71238898038469" upper="4.71238898038469" velocity="1"/>
    <dynamics damping="0" friction="0"/>
  </joint>
  <link name="arm1_J2">
    <visual>
      <origin rpy="0 0 0" xyz="0 0 0"/>
      <geometry>
        <mesh filename="J2.stl" scale="1 1 1"/>
      </geometry>
    </visual>
    <collision>
      <origin rpy="0 0 0" xyz="0 0 0"/>
      <geometry>
        <mesh filename="J2.stl" scale="1 1 1"/>
      </geometry>
    </collision>
    <inertial>
      <mass value="12.93"/>
      <origin rpy="0.000000 0.000000 0.000000" xyz="0.000000 0.000000 0.000000"/>
      <inertia ixx="0.42175" ixy="0" ixz="0" iyy="0.42175" iyz="0" izz="0.0363"/>
    </inertial>
  </link>
  <joint name="arm1_joint_2" type="revolute">
    <parent link="arm1_J1"/>
    <child link="arm1_J2"/>
    <origin rpy="0.000000 0.000000 0.000000" xyz="0.000000 0.000000 0.109000"/>
    <axis xyz="-0.000000 1.000000 -0.000000"/>
    <limit effort="175" lower="-2.61799387799149" upper="2.61799387799149" velocity="1"/>
    <dynamics damping="0" friction="0"/>
  </joint>
  <link name="arm1_J3">
    <visual>
      <origin rpy="0 0 0" xyz="0 0 0"/>
      <geometry>
        <mesh filename="J3.stl" scale="1 1 1"/>
      </geometry>
    </visual>
    <collision>
      <origin rpy="0 0 0" xyz="0 0 0"/>
      <geometry>
        <mesh filename="J3.stl" scale="1 1 1"/>
      </geometry>
    </collision>
    <inertial>
      <mass value="3.87"/>
      <origin rpy="0.000000 0.000000 0.000000" xyz="0.000000 0.000000 0.000000"/>
      <inertia ixx="0.111" ixy="0" ixz="0" iyy="0.111" iyz="0" izz="0.01"/>
    </inertial>
  </link>
  <joint name="arm1_joint_3" type="revolute">
    <parent link="arm1_J2"/>
    <child link="arm1_J3"/>
    <origin rpy="0.000000 0.000000 0.000000" xyz="0.000000 0.000000 0.510000"/>
    <axis xyz="-0.000000 1.000000 -0.000000"/>
    <limit effort="100" lower="-2.61799387799149" upper="2.61799387799149" velocity="1"/>
    <dynamics damping="0" friction="0"/>
  </joint>
  <link name="arm1_J4">
    <visual>
      <origin rpy="0 0 0" xyz="0 0 0"/>
      <geometry>
        <mesh filename="J4.stl" scale="1 1 1"/>
      </geometry>
    </visual>
    <collision>
      <origin rpy="0 0 0" xyz="0 0 0"/>
      <geometry>
        <mesh filename="J4.stl" scale="1 1 1"/>
      </geometry>
    </collision>
    <inertial>
      <mass value="1.96"/>
      <origin rpy="0.000000 0.000000 0.000000" xyz="0.000000 0.000000 0.000000"/>
      <inertia ixx="0.0051" ixy="0" ixz="0" iyy="0.0051" iyz="0" izz="0.0055"/>
    </inertial>
  </link>
  <joint name="arm1_joint_4" type="revolute">
    <parent link="arm1_J3"/>
    <child link="arm1_J4"/>
    <origin rpy="0.000000 0.000000 0.000000" xyz="0.000000 -0.030000 0.302000"/>
    <axis xyz="-0.000000 -0.000000 1.000000"/>
    <limit effort="75" lower="-4.71238898038469" upper="4.71238898038469" velocity="1"/>
    <dynamics damping="0" friction="0"/>
  </joint>
  <link name="arm1_J5">
    <visual>
      <origin rpy="0 0 0" xyz="0 0 0"/>
      <geometry>
        <mesh filename="J5.stl" scale="1 1 1"/>
      </geometry>
    </visual>
    <collision>
      <origin rpy="0 0 0" xyz="0 0 0"/>
      <geometry>
        <mesh filename="J5.stl" scale="1 1 1"/>
      </geometry>
    </collision>
    <inertial>
      <mass value="1.96"/>
      <origin rpy="0.000000 0.000000 0.000000" xyz="0.000000 0.000000 0.000000"/>
      <inertia ixx="0.004" ixy="0" ixz="0" iyy="0.004" iyz="0" izz="0.0055"/>
    </inertial>
  </link>
  <joint name="arm1_joint_5" type="revolute">
    <parent link="arm1_J4"/>
    <child link="arm1_J5"/>
    <origin rpy="0.000000 0.000000 0.000000" xyz="0.000000 0.030000 0.088000"/>
    <axis xyz="-0.000000 1.000000 -0.000000"/>
    <limit effort="75" lower="-2.61799387799149" upper="2.61799387799149" velocity="1"/>
    <dynamics damping="0" friction="0"/>
  </joint>
  <link name="arm1_J6">
    <visual>
      <origin rpy="0 0 0" xyz="0 0 0"/>
      <geometry>
        <mesh filename="J6.stl" scale="1 1 1"/>
      </geometry>
    </visual>
    <collision>
      <origin rpy="0 0 0" xyz="0 0 0"/>
      <geometry>
        <mesh filename="J6.stl" scale="1 1 1"/>
      </geometry>
    </collision>
    <inertial>
      <mass value="0.202"/>
      <origin rpy="0.000000 0.000000 0.000000" xyz="0.000000 0.000000 0.000000"/>
      <inertia ixx="0.00011" ixy="0" ixz="0" iyy="0.00011" iyz="0" izz="0.0002"/>
    </inertial>
  </link>
  <joint name="arm1_joint_6" type="revolute">
    <parent link="arm1_J5"/>
    <child link="arm1_J6"/>
    <origin rpy="0.000000 0.000000 0.000000" xyz="0.000000 0.120000 0.160000"/>
    <axis xyz="-0.000000 -0.000000 1.000000"/>
    <limit effort="75" lower="-6.28318530717959" upper="6.28318530717959" velocity="1"/>
    <dynamics damping="0" friction="0"/>
  </joint>
  <link name="arm1_end1_link"/>
  <joint name="arm1_end1_joint" type="fixed">
    <parent link="arm1_J6"/>
    <child link="arm1_end1_link"/>
  </joint>
  <!-- custom add END -->
  <!-- custom mod -->
  <!-- Add use_ros2_control_plugin to use this with Ignition Gazebo -->
  <!-- custom mod -->
  <!-- Add use_ros2_control_plugin to use this with Ignition Gazebo -->
  <!-- custom mod -->
  <!-- Add use_ros2_control_plugin to use this with Ignition Gazebo -->
  <ros2_control name="RobotiqGripperHardwareInterface" type="system">
    <!-- Plugins -->
    <hardware>
      <plugin>ign_ros2_control/IgnitionSystem</plugin>
    </hardware>
    <!-- Joint interfaces -->
    <!-- With Ignition or Hardware, they handle mimic joints, so we only need this command interface activated -->
    <joint name="hand1_virtual_opening_distance_joint">
      <command_interface name="position"/>
      <state_interface name="position">
        <param name="initial_value">0.0</param>
      </state_interface>
      <state_interface name="velocity"/>
    </joint>
    <joint name="hand1_robotiq_85_left_knuckle_joint">
      <param name="mimic">hand1_virtual_opening_distance_joint</param>
      <param name="multiplier">9.328235294117647</param>
    </joint>
    <joint name="hand1_robotiq_85_right_knuckle_joint">
      <param name="mimic">hand1_virtual_opening_distance_joint</param>
      <param name="multiplier">-9.328235294117647</param>
    </joint>
    <joint name="hand1_robotiq_85_left_inner_knuckle_joint">
      <param name="mimic">hand1_virtual_opening_distance_joint</param>
      <param name="multiplier">9.328235294117647</param>
    </joint>
    <joint name="hand1_robotiq_85_right_inner_knuckle_joint">
      <param name="mimic">hand1_virtual_opening_distance_joint</param>
      <param name="multiplier">-9.328235294117647</param>
    </joint>
    <joint name="hand1_robotiq_85_left_finger_tip_joint">
      <param name="mimic">hand1_virtual_opening_distance_joint</param>
      <param name="multiplier">-9.328235294117647</param>
    </joint>
    <joint name="hand1_robotiq_85_right_finger_tip_joint">
      <param name="mimic">hand1_virtual_opening_distance_joint</param>
      <param name="multiplier">9.328235294117647</param>
    </joint>
    <!-- custom add END -->
    <sensor name="hand1_force_limit">
      <command_interface name="effort"/>
    </sensor>
  </ros2_control>
  <!-- custom add END -->
  <!-- custom mod -->
  <!-- Add use_ros2_control_plugin to use this with Ignition Gazebo -->
  <link name="hand1_base_link"/>
  <link name="hand1_robotiq_85_base_link">
    <visual>
      <geometry>
        <mesh filename="robotiq_arg2f_85_base_link.stl"/>
      </geometry>
    </visual>
    <collision>
      <geometry>
        <mesh filename="robotiq_arg2f_85_base_link.stl"/>
      </geometry>
    </collision>
    <inertial>
      <origin rpy="0 0 0" xyz="0.0 2.274e-05 0.03232288"/>
      <mass value="6.6320197e-01"/>
      <inertia ixx="5.1617816e-04" ixy="2.936e-8" ixz="0.0" iyy="5.8802208e-04" iyz="-3.2296e-7" izz="3.9462776e-04"/>
    </inertial>
  </link>
  <link name="hand1_robotiq_85_left_knuckle_link">
    <visual>
      <geometry>
        <mesh filename="robotiq_arg2f_85_outer_knuckle.stl"/>
      </geometry>
    </visual>
    <collision>
      <geometry>
        <mesh filename="robotiq_arg2f_85_outer_knuckle.stl"/>
      </geometry>
    </collision>
    <inertial>
      <origin rpy="0 0 0" xyz="0.01213197 0.0002 -0.00058647"/>
      <mass value="1.384773208e-02"/>
      <inertia ixx="3.5232e-7" ixy="0.0" ixz="1.1744e-7" iyy="2.31944e-6" iyz="0" izz="2.23136e-6"/>
    </inertial>
  </link>
  <link name="hand1_robotiq_85_right_knuckle_link">
    <visual>
      <geometry>
        <mesh filename="robotiq_arg2f_85_outer_knuckle.stl"/>
      </geometry>
    </visual>
    <collision>
      <geometry>
        <mesh filename="robotiq_arg2f_85_outer_knuckle.stl"/>
      </geometry>
    </collision>
    <inertial>
      <origin rpy="0 0 0" xyz="-0.01213197 0.0002 -0.00058647"/>
      <mass value="1.384773208e-02"/>
      <inertia ixx="3.5232e-7" ixy="0.0" ixz="-1.1744e-7" iyy="2.31944e-6" iyz="0.0" izz="2.23136e-6"/>
    </inertial>
  </link>
  <link name="hand1_robotiq_85_left_finger_link">
    <visual>
      <geometry>
        <mesh filename="robotiq_arg2f_85_outer_finger.stl"/>
      </geometry>
    </visual>
    <collision>
      <geometry>
        <mesh filename="robotiq_arg2f_85_outer_finger.stl"/>
      </geometry>
    </collision>
    <inertial>
      <origin rpy="0 0 0" xyz="0.00346899 -0.00079447 0.01867121"/>
      <mass value="4.260376752e-02"/>
      <inertia ixx="1.385792000000000e-05" ixy="0.0" ixz="-2.17264e-06" iyy="1.183208e-05" iyz="0.0" izz="5.19672e-06"/>
    </inertial>
  </link>
  <link name="hand1_robotiq_85_right_finger_link">
    <visual>
      <geometry>
        <mesh filename="robotiq_arg2f_85_outer_finger.stl"/>
      </geometry>
    </visual>
    <collision>
      <geometry>
        <mesh filename="robotiq_arg2f_85_outer_finger.stl"/>
      </geometry>
    </collision>
    <inertial>
      <origin rpy="0 0 0" xyz="-0.00346899 -5.53e-06 0.01867121"/>
      <mass value="4.260376752000000e-02"/>
      <inertia ixx="1.385792e-05" ixy="0.0" ixz="2.17264e-06" iyy="1.183208e-05" iyz="0.0" izz="5.19672e-06"/>
    </inertial>
  </link>
  <link name="hand1_robotiq_85_left_inner_knuckle_link">
    <visual>
      <geometry>
        <mesh filename="robotiq_arg2f_85_inner_knuckle.stl"/>
      </geometry>
    </visual>
    <collision>
      <geometry>
        <mesh filename="robotiq_arg2f_85_inner_knuckle.stl"/>
      </geometry>
    </collision>
    <inertial>
      <origin rpy="0 0 0" xyz="0.01897699 0.00015001 0.02247101"/>
      <mass value="2.969376448e-02"/>
      <inertia ixx="9.57136e-06" ixy="0.0" ixz="-3.93424e-06" iyy="8.69056e-06" iyz="0.0" izz="8.19144e-06"/>
    </inertial>
  </link>
  <link name="hand1_robotiq_85_right_inner_knuckle_link">
    <visual>
      <geometry>
        <mesh filename="robotiq_arg2f_85_inner_knuckle.stl"/>
      </geometry>
    </visual>
    <collision>
      <geometry>
        <mesh filename="robotiq_arg2f_85_inner_knuckle.stl"/>
      </geometry>
    </collision>
    <inertial>
      <origin rpy="0 0 0" xyz="-0.01926824 5.001e-05 0.02222178"/>
      <mass value="2.969376448e-02"/>
      <inertia ixx="9.42456e-06" ixy="0.0" ixz="3.9636e-06" iyy="8.69056e-06" iyz="0.0" izz="8.33824e-06"/>
    </inertial>
  </link>
  <link name="hand1_robotiq_85_left_finger_tip_link">
    <visual>
      <geometry>
        <mesh filename="robotiq_arg2f_85_inner_finger.stl"/>
      </geometry>
    </visual>
    <collision>
      <geometry>
        <mesh filename="robotiq_arg2f_85_inner_finger.stl"/>
      </geometry>
      <surface>
        <friction>
          <ode>
            <mu1>100000.0</mu1>
            <mu2>100000.0</mu2>
          </ode>
        </friction>
        <contact>
          <ode>
            <kp>1e+5</kp>
            <kd>1</kd>
            <soft_cfm>0</soft_cfm>
            <soft_erp>0.2</soft_erp>
            <minDepth>0.002</minDepth>
            <maxVel>0</maxVel>
          </ode>
        </contact>
      </surface>
    </collision>
    <inertial>
      <origin rpy="0 0 0" xyz="-0.01456706 -0.0008 0.01649701"/>
      <mass value="4.268588744e-02"/>
      <inertia ixx="1.048152e-05" ixy="0.0" ixz="3.5232e-6" iyy="1.197888e-05" iyz="0.0" izz="4.22784e-06"/>
    </inertial>
  </link>
  <link name="hand1_robotiq_85_right_finger_tip_link">
    <visual>
      <geometry>
        <mesh filename="robotiq_arg2f_85_inner_finger.stl"/>
      </geometry>
    </visual>
    <collision>
      <geometry>
        <mesh filename="robotiq_arg2f_85_inner_finger.stl"/>
      </geometry>
      <surface>
        <friction>
          <ode>
            <mu1>100000.0</mu1>
            <mu2>100000.0</mu2>
          </ode>
        </friction>
        <contact>
          <ode>
            <kp>1e+5</kp>
            <kd>1</kd>
            <soft_cfm>0</soft_cfm>
            <soft_erp>0.2</soft_erp>
            <minDepth>0.002</minDepth>
            <maxVel>0</maxVel>
          </ode>
        </contact>
      </surface>
    </collision>
    <inertial>
      <origin rpy="0 0 0" xyz="0.01456706 5e-05 0.01649701"/>
      <mass value="4.268588744e-02"/>
      <inertia ixx="1.048152e-05" ixy="0.0" ixz="-3.5232e-06" iyy="1.197888e-05" iyz="0.0" izz="4.22784e-06"/>
    </inertial>
  </link>
  <link name="hand1_end1_link"/>
  <link name="hand1_end2_link"/>
  <joint name="hand1_base_joint" type="fixed">
    <parent link="handcover_end1_link"/>
    <child link="hand1_base_link"/>
    <origin rpy="0 0 0" xyz="0.0 0.0 0.0"/>
  </joint>
  <joint name="hand1_robotiq_85_base_joint" type="fixed">
    <parent link="hand1_base_link"/>
    <child link="hand1_robotiq_85_base_link"/>
    <origin rpy="0 0 -1.5707963267948966" xyz="0.0 0.0 0.0"/>
  </joint>
  <!-- custom mod TOP -->
  <!-- Add <inertial> tag to suppress the tag does not exist warning on startup Ignition Gazebo -->
  <!--
        <link name="${prefix}virtual_opening_distance_link" />
        -->
  <link name="hand1_virtual_opening_distance_link">
    <inertial>
      <origin rpy="0 0 0" xyz="0 0 0"/>
      <mass value="0.001"/>
      <inertia ixx="0.0001" ixy="0.0" ixz="0.0" iyy="0.0001" iyz="0.0" izz="0.0001"/>
    </inertial>
  </link>
  <!-- custom mod END -->
  <joint name="hand1_virtual_opening_distance_joint" type="prismatic">
    <parent link="world"/>
    <child link="hand1_virtual_opening_distance_link"/>
    <origin rpy="0 0 0" xyz="0.0 0.0 0.0"/>
    <limit effort="50" lower="0.0" upper="0.085" velocity="0.5"/>
  </joint>
  <joint name="hand1_robotiq_85_left_knuckle_joint" type="revolute">
    <parent link="hand1_robotiq_85_base_link"/>
    <child link="hand1_robotiq_85_left_knuckle_link"/>
    <axis xyz="0 -1 0"/>
    <origin rpy="0 0 0" xyz="0.03060114 0.0 0.05490452"/>
    <!-- custom mod TOP -->
    <!-- Increase the range of motion a little, as it does not drive as instructed, probably due to a problem with the Ignition gazebo -->
    <!--
            <limit lower="0.0" upper="0.8" velocity="0.5" effort="50" />
            -->
    <limit effort="50" lower="-0.001" upper="0.8" velocity="0.5"/>
    <!-- custom mod END -->
    <dynamics damping="1.0e-6" friction="0.1"/>
    <!-- custom add -->
    <!-- Set friction to joints in IgnitionGazebo to prevent shape collapse at the start of simulation -->
    <mimic joint="hand1_virtual_opening_distance_joint" multiplier="9.328235294117647"/>
  </joint>
  <joint name="hand1_robotiq_85_right_knuckle_joint" type="revolute">
    <parent link="hand1_robotiq_85_base_link"/>
    <child link="hand1_robotiq_85_right_knuckle_link"/>
    <axis xyz="0 -1 0"/>
    <origin rpy="0 0 0" xyz="-0.03060114 0.0 0.05490452"/>
    <!-- custom mod TOP -->
    <!-- Increase the range of motion a little, as it does not drive as instructed, probably due to a problem with the Ignition gazebo -->
    <!--
            <limit lower="-0.8" upper="0.0" velocity="0.5" effort="50" />
            -->
    <limit effort="50" lower="-0.8" upper="0.001" velocity="0.5"/>
    <!-- custom mod END -->
    <dynamics damping="1.0e-6" friction="0.1"/>
    <!-- custom add -->
    <!-- Set friction to joints in IgnitionGazebo to prevent shape collapse at the start of simulation -->
    <!-- custom mod TOP -->
    <!-- Change mimic to A to prevent Ignition Gazebo from killing due to nesting of mimic. -->
    <!--
            <mimic joint="${prefix}robotiq_85_left_knuckle_joint" multiplier="-1" />
            -->
    <mimic joint="hand1_virtual_opening_distance_joint" multiplier="-9.328235294117647"/>
    <!-- custom mod END -->
  </joint>
  <joint name="hand1_robotiq_85_left_finger_joint" type="fixed">
    <parent link="hand1_robotiq_85_left_knuckle_link"/>
    <child link="hand1_robotiq_85_left_finger_link"/>
    <origin rpy="0 0 0" xyz="0.03152616 0.0 -0.00376347"/>
  </joint>
  <joint name="hand1_robotiq_85_right_finger_joint" type="fixed">
    <parent link="hand1_robotiq_85_right_knuckle_link"/>
    <child link="hand1_robotiq_85_right_finger_link"/>
    <origin rpy="0 0 0" xyz="-0.03152616 0.0 -0.00376347"/>
  </joint>
  <joint name="hand1_robotiq_85_left_inner_knuckle_joint" type="revolute">
    <parent link="hand1_robotiq_85_base_link"/>
    <child link="hand1_robotiq_85_left_inner_knuckle_link"/>
    <axis xyz="0 -1 0"/>
    <origin rpy="0 0 0" xyz="0.0127 0.0 0.06142"/>
    <limit effort="50" lower="-0.8757" upper="0.8757" velocity="0.5"/>
    <dynamics damping="1.0e-6" friction="0.1"/>
    <!-- custom add -->
    <!-- Set friction to joints in IgnitionGazebo to prevent shape collapse at the start of simulation -->
    <mimic joint="hand1_virtual_opening_distance_joint" multiplier="9.328235294117647"/>
  </joint>
  <joint name="hand1_robotiq_85_right_inner_knuckle_joint" type="revolute">
    <parent link="hand1_robotiq_85_base_link"/>
    <child link="hand1_robotiq_85_right_inner_knuckle_link"/>
    <axis xyz="0 -1 0"/>
    <origin rpy="0 0 0" xyz="-0.0127 0.0 0.06142"/>
    <limit effort="50" lower="-0.8757" upper="0.8757" velocity="0.5"/>
    <dynamics damping="1.0e-6" friction="0.1"/>
    <!-- custom add -->
    <!-- Set friction to joints in IgnitionGazebo to prevent shape collapse at the start of simulation -->
    <mimic joint="hand1_virtual_opening_distance_joint" multiplier="-9.328235294117647"/>
  </joint>
  <joint name="hand1_robotiq_85_left_finger_tip_joint" type="revolute">
    <parent link="hand1_robotiq_85_left_finger_link"/>
    <child link="hand1_robotiq_85_left_finger_tip_link"/>
    <axis xyz="0 -1 0"/>
    <origin rpy="0 0 0" xyz="0.00563134 0.0 0.04718515"/>
    <limit effort="50" lower="-0.8757" upper="0.8757" velocity="0.5"/>
    <dynamics damping="1.0e-6" friction="0.1"/>
    <!-- custom add -->
    <!-- Set friction to joints in IgnitionGazebo to prevent shape collapse at the start of simulation -->
    <mimic joint="hand1_virtual_opening_distance_joint" multiplier="-9.328235294117647"/>
  </joint>
  <joint name="hand1_robotiq_85_right_finger_tip_joint" type="revolute">
    <parent link="hand1_robotiq_85_right_finger_link"/>
    <child link="hand1_robotiq_85_right_finger_tip_link"/>
    <axis xyz="0 -1 0"/>
    <origin rpy="0 0 0" xyz="-0.00563134 0.0 0.04718515"/>
    <limit effort="50" lower="-0.8757" upper="0.8757" velocity="0.5"/>
    <dynamics damping="1.0e-6" friction="0.1"/>
    <!-- custom add -->
    <!-- Set friction to joints in IgnitionGazebo to prevent shape collapse at the start of simulation -->
    <mimic joint="hand1_virtual_opening_distance_joint" multiplier="9.328235294117647"/>
  </joint>
  <!-- custom add END -->
  <joint name="hand1_end1_joint" type="fixed">
    <origin rpy="-1.5707963267948966 0 1.5707963267948966" xyz="-0.025 0 0.03"/>
    <parent link="hand1_robotiq_85_left_finger_tip_link"/>
    <child link="hand1_end1_link"/>
  </joint>
  <joint name="hand1_end2_joint" type="fixed">
    <origin rpy="-1.5707963267948966 0 -1.5707963267948966" xyz="0.025 0 0.03"/>
    <parent link="hand1_robotiq_85_right_finger_tip_link"/>
    <child link="hand1_end2_link"/>
  </joint>
  <link name="hand1_top1_link"/>
  <joint name="hand1_top1_joint" type="fixed">
    <parent link="hand1_end1_link"/>
    <child link="hand1_top1_link"/>
    <origin rpy="0 0 0" xyz="0 -0.025 0"/>
  </joint>
  <link name="hand1_top2_link"/>
  <joint name="hand1_top2_joint" type="fixed">
    <parent link="hand1_end2_link"/>
    <child link="hand1_top2_link"/>
    <origin rpy="0 0 0" xyz="0 -0.025 0"/>
  </joint>
  <link name="hand1_rotate_finger1_link">
    <visual>
      <geometry>
        <box size="0.1 0.2 0.05"/>
      </geometry>
    </visual>
    <collision>
      <geometry>
        <box size="0.1 0.2 0.05"/>
      </geometry>
    </collision>
    <inertial>
      <!-- This link fixes to world, so inertial tag set dummy value. -->
      <mass value="0.01"/>
      <inertia ixx="0.001" ixy="0.0" ixz="0.0" iyy="0.001" iyz="0.0" izz="0.001"/>
    </inertial>
  </link>
  <gazebo reference="hand1_rotate_finger1_link">
    <mu1 value="1.0"/>
    <mu2 value="1.0"/>
    <visual>
      <material>
        <ambient>0.8 0.8 0.8 1.0</ambient>
        <diffuse>0.8 0.8 0.8 1.0</diffuse>
        <specular>0.8 0.8 0.8 1.0</specular>
      </material>
    </visual>
  </gazebo>
  <joint name="hand1_rotate_finger1_joint" type="continuous">
    <parent link="hand1_top1_link"/>
    <child link="hand1_rotate_finger1_link"/>
    <origin rpy="0.0 0.0 0.0" xyz="-0.0 -0.1 -0.0"/>
    <limit effort="100" lower="-1.0" upper="1.0" velocity="0.5"/>
    <safety_controller k_position="100" k_velocity="20"/>
    <axis xyz="0 1 0"/>
  </joint>
  <ros2_control name="hand1_rotate_finger1_hardware_interface" type="system">
    <!-- Plugins -->
    <hardware>
      <plugin>ign_ros2_control/IgnitionSystem</plugin>
    </hardware>
    <!-- Joint interfaces -->
    <!-- With Ignition or Hardware, they handle mimic joints, so we only need this command interface activated -->
    <joint name="hand1_rotate_finger1_joint">
      <command_interface name="position">
        <param name="min">-1.5</param>
        <param name="max">1.5</param>
      </command_interface>
      <state_interface name="position">
        <param name="initial_value">0</param>
      </state_interface>
      <state_interface name="velocity"/>
    </joint>
  </ros2_control>
  <link name="hand1_rotate_finger2_link">
    <visual>
      <geometry>
        <box size="0.1 0.2 0.05"/>
      </geometry>
    </visual>
    <collision>
      <geometry>
        <box size="0.1 0.2 0.05"/>
      </geometry>
    </collision>
    <inertial>
      <!-- This link fixes to world, so inertial tag set dummy value. -->
      <mass value="0.01"/>
      <inertia ixx="0.001" ixy="0.0" ixz="0.0" iyy="0.001" iyz="0.0" izz="0.001"/>
    </inertial>
  </link>
  <gazebo reference="hand1_rotate_finger2_link">
    <mu1 value="1.0"/>
    <mu2 value="1.0"/>
    <visual>
      <material>
        <ambient>0.8 0.8 0.8 1.0</ambient>
        <diffuse>0.8 0.8 0.8 1.0</diffuse>
        <specular>0.8 0.8 0.8 1.0</specular>
      </material>
    </visual>
  </gazebo>
  <joint name="hand1_rotate_finger2_joint" type="continuous">
    <parent link="hand1_top2_link"/>
    <child link="hand1_rotate_finger2_link"/>
    <origin rpy="0.0 0.0 0.0" xyz="-0.0 -0.1 -0.0"/>
    <limit effort="100" lower="-1.0" upper="1.0" velocity="0.5"/>
    <safety_controller k_position="100" k_velocity="20"/>
    <axis xyz="0 1 0"/>
  </joint>
  <ros2_control name="hand1_rotate_finger2_hardware_interface" type="system">
    <!-- Plugins -->
    <hardware>
      <plugin>ign_ros2_control/IgnitionSystem</plugin>
    </hardware>
    <!-- Joint interfaces -->
    <!-- With Ignition or Hardware, they handle mimic joints, so we only need this command interface activated -->
    <joint name="hand1_rotate_finger2_joint">
      <command_interface name="position">
        <param name="min">-1.5</param>
        <param name="max">1.5</param>
      </command_interface>
      <state_interface name="position">
        <param name="initial_value">0</param>
      </state_interface>
      <state_interface name="velocity"/>
    </joint>
  </ros2_control>
  <!-- custom add END -->
  <link name="robotstand_base_link">
    <visual>
      <geometry>
        <box size=".1 .1 .1" />
      </geometry>
    </visual>
    <collision>
      <geometry>
        <box size=".1 .1 .1" />
      </geometry>
    </collision>
    <inertial>
      <!-- This link fixes to world, so inertial tag set dummy value. -->
      <mass value="0.01"/>
      <inertia ixx="0.001" ixy="0.0" ixz="0.0" iyy="0.001" iyz="0.0" izz="0.001"/>
    </inertial>
  </link>
  <gazebo reference="robotstand_base_link">
    <mu1 value="1.0"/>
    <mu2 value="1.0"/>
    <visual>
      <material>
        <ambient>0.8 0.8 0.8 1.0</ambient>
        <diffuse>0.8 0.8 0.8 1.0</diffuse>
        <specular>0.8 0.8 0.8 1.0</specular>
      </material>
    </visual>
  </gazebo>
  <link name="robotstand_lifter_link"/>
  <joint name="robotstand_lifter_joint" type="fixed">
    <origin rpy="0 0 0" xyz="0 0 0.0"/>
    <parent link="robotstand_base_link"/>
    <child link="robotstand_lifter_link"/>
  </joint>
  <link name="robotstand_stage_link">
    <visual>
      <geometry>
        <box size=".1 .1 .1" />
      </geometry>
    </visual>
    <collision>
      <geometry>
        <box size=".1 .1 .1" />
      </geometry>
    </collision>
    <inertial>
      <!-- This link fixes to world, so inertial tag set dummy value. -->
      <mass value="0.01"/>
      <inertia ixx="0.001" ixy="0.0" ixz="0.0" iyy="0.001" iyz="0.0" izz="0.001"/>
    </inertial>
  </link>
  <gazebo reference="robotstand_stage_link">
    <mu1 value="1.0"/>
    <mu2 value="1.0"/>
    <visual>
      <material>
        <ambient>0.8 0.8 0.8 1.0</ambient>
        <diffuse>0.8 0.8 0.8 1.0</diffuse>
        <specular>0.8 0.8 0.8 1.0</specular>
      </material>
    </visual>
  </gazebo>
  <joint name="robotstand_stage_joint" type="prismatic">
    <parent link="robotstand_lifter_link"/>
    <child link="robotstand_stage_link"/>
    <origin rpy="0 0 0" xyz="0.0 -0.11 0.8"/>
    <limit effort="1000" lower="-0.6" upper="0.1" velocity="0.01"/>
    <axis xyz="0 0 1"/>
    <dynamics damping="100"/>
  </joint>
  <link name="robotstand_end_link"/>
  <joint name="robotstand_end_joint" type="fixed">
    <origin rpy="0 0 1.570" xyz="0.0 0 0.01"/>
    <parent link="robotstand_stage_link"/>
    <child link="robotstand_end_link"/>
  </joint>
  <ros2_control name="robotstand_lifter_hardware_interface" type="system">
    <!-- Plugins -->
    <hardware>
      <plugin>ign_ros2_control/IgnitionSystem</plugin>
    </hardware>
    <!-- Joint interfaces -->
    <!-- With Ignition or Hardware, they handle mimic joints, so we only need this command interface activated -->
    <joint name="robotstand_stage_joint">
      <command_interface name="position">
        <param name="min">-0.6</param>
        <param name="max">0.1</param>
      </command_interface>
      <state_interface name="position">
        <param name="initial_value">-0.3</param>
      </state_interface>
      <state_interface name="velocity"/>
    </joint>
  </ros2_control>
  <gazebo name="ign_plugin_lifter">
    <plugin filename="ignition-gazebo-joint-position-controller-system" name="ignition::gazebo::systems::JointPositionController">
      <joint_name>robotstand_stage_joint</joint_name>
      <p_gain>100</p_gain>
      <i_gain>0.1</i_gain>
      <d_gain>0.01</d_gain>
      <i_max>1</i_max>
      <i_min>-1</i_min>
      <cmd_max>1000</cmd_max>
      <cmd_min>-1000</cmd_min>
    </plugin>
  </gazebo>
  <link name="handcover_base_link">
    <visual>
      <geometry>
        <box size=".1 .1 .1" />
      </geometry>
    </visual>
    <collision>
      <geometry>
        <box size=".1 .1 .1" />
      </geometry>
    </collision>
    <inertial>
      <mass value="0.01"/>
      <inertia ixx="0.001" ixy="0.0" ixz="0.0" iyy="0.001" iyz="0.0" izz="0.001"/>
    </inertial>
  </link>
  <gazebo reference="handcover_base_link">
    <mu1 value="1.0"/>
    <mu2 value="1.0"/>
    <visual>
      <material>
        <ambient>0.8 0.8 0.8 1.0</ambient>
        <diffuse>0.8 0.8 0.8 1.0</diffuse>
        <specular>0.8 0.8 0.8 1.0</specular>
      </material>
    </visual>
  </gazebo>
  <!-- end1_link is the link to connect to hand -->
  <link name="handcover_end1_link"/>
  <joint name="handcover_end1_link_joint" type="fixed">
    <origin rpy="0 0 0" xyz="0 0 0.1393"/>
    <parent link="handcover_base_link"/>
    <child link="handcover_end1_link"/>
  </joint>
  <joint name="robotstand_arm_joint" type="fixed">
    <parent link="robotstand_end_link"/>
    <child link="arm1_base_link"/>
  </joint>
  <!-- connect handcover/arm -->
  <joint name="arm_handcover_joint" type="fixed">
    <parent link="arm1_end1_link"/>
    <child link="handcover_base_link"/>
  </joint>
  <!-- nothing to do here as it is connected in robotiq_2f_85_gripper.macro.xacro -->
  <!-- set grip end_link -->
  <link name="grip_end_link"/>
  <joint name="grip_end_link_joint" type="fixed">
    <parent link="hand1_base_link"/>
    <child link="grip_end_link"/>
    <origin rpy="0.0 0.0 0.0" xyz="0.0 0.0 0.14"/>
  </joint>
  <!-- fix arm to world -->
  <link name="world"/>
  <joint name="world_joint" type="fixed">
    <parent link="world"/>
    <child link="robotstand_base_link"/>
  </joint>
  <!-- add rotate finger top -->
  <gazebo reference="hand1_robotiq_85_left_finger_tip_link">
    <mu1 value="1.0"/>
    <mu2 value="1.0"/>
  </gazebo>
  <gazebo reference="hand1_robotiq_85_right_finger_tip_link">
    <mu1 value="1.0"/>
    <mu2 value="1.0"/>
  </gazebo>
  <gazebo>
    <plugin filename="libign_ros2_control-system.so" name="ign_ros2_control::IgnitionROS2ControlPlugin">
      <parameters>/home/mouri/workspace/install/ign_ros2_robot2world_sample/share/ign_ros2_robot2world_sample/config/hand1_controllers.yaml</parameters>
      <parameters>/home/mouri/workspace/install/ign_ros2_robot2world_sample/share/ign_ros2_robot2world_sample/config/arm1_controllers.yaml</parameters>
      <parameters>/home/mouri/workspace/install/ign_ros2_robot2world_sample/share/ign_ros2_robot2world_sample/config/robotstand_controllers.yaml</parameters>
    </plugin>
  </gazebo>
</robot>